<?xml version="1.0" encoding="UTF-8"?>
<testsuite hostname="EPBYMINW0918" name="by.epam.testmodule4.BuketTest" tests="6" failures="1" timestamp="12 May 2015 15:51:40 GMT" time="0.93" errors="0">
  <testcase name="checkNameBouquetFromDB" time="0.871" classname="by.epam.testmodule4.BuketTest">
    <failure type="java.lang.AssertionError" message="expected:&amp;lt;ExampleDB&amp;gt; but was:&amp;lt;Test&amp;gt;">
      <![CDATA[java.lang.AssertionError: expected:<ExampleDB> but was:<Test>
	at org.testng.Assert.fail(Assert.java:89)
	at org.testng.Assert.failNotEquals(Assert.java:489)
	at org.testng.Assert.assertEquals(Assert.java:118)
	at org.testng.Assert.assertEquals(Assert.java:171)
	at org.testng.Assert.assertEquals(Assert.java:181)
	at by.epam.testmodule4.BuketTest.checkNameBouquetFromDB(BuketTest.java:33)
	at sun.reflect.NativeMethodAccessorImpl.invoke0(Native Method)
	at sun.reflect.NativeMethodAccessorImpl.invoke(Unknown Source)
	at sun.reflect.DelegatingMethodAccessorImpl.invoke(Unknown Source)
	at java.lang.reflect.Method.invoke(Unknown Source)
	at org.testng.internal.MethodInvocationHelper.invokeMethod(MethodInvocationHelper.java:80)
	at org.testng.internal.Invoker.invokeMethod(Invoker.java:673)
	at org.testng.internal.Invoker.invokeTestMethod(Invoker.java:842)
	at org.testng.internal.Invoker.invokeTestMethods(Invoker.java:1166)
	at org.testng.internal.TestMethodWorker.invokeTestMethods(TestMethodWorker.java:125)
	at org.testng.internal.TestMethodWorker.run(TestMethodWorker.java:109)
	at org.testng.TestRunner.runWorkers(TestRunner.java:1178)
	at org.testng.TestRunner.privateRun(TestRunner.java:757)
	at org.testng.TestRunner.run(TestRunner.java:608)
	at org.testng.SuiteRunner.runTest(SuiteRunner.java:334)
	at org.testng.SuiteRunner.runSequentially(SuiteRunner.java:329)
	at org.testng.SuiteRunner.privateRun(SuiteRunner.java:291)
	at org.testng.SuiteRunner.run(SuiteRunner.java:240)
	at org.testng.SuiteRunnerWorker.runSuite(SuiteRunnerWorker.java:52)
	at org.testng.SuiteRunnerWorker.run(SuiteRunnerWorker.java:86)
	at org.testng.TestNG.runSuitesSequentially(TestNG.java:1158)
	at org.testng.TestNG.runSuitesLocally(TestNG.java:1083)
	at org.testng.TestNG.run(TestNG.java:999)
	at org.testng.remote.RemoteTestNG.run(RemoteTestNG.java:111)
	at org.testng.remote.RemoteTestNG.initAndRun(RemoteTestNG.java:203)
	at org.testng.remote.RemoteTestNG.main(RemoteTestNG.java:174)
]]>
    </failure>
  </testcase>
  <testcase name="checkNameBouquetFromXML" time="0.02" classname="by.epam.testmodule4.BuketTest"/>
  <testcase name="testAddFlower" time="0.001" classname="by.epam.testmodule4.BuketTest"/>
  <testcase name="testBuketSumma" time="0.007" classname="by.epam.testmodule4.BuketTest"/>
  <testcase name="divisionWithException" time="0.001" classname="by.epam.testmodule4.ExceptionTest"/>
  <testcase name="verifyException" time="0.001" classname="by.epam.testmodule4.ExceptionTest"/>
</testsuite>
